Workbook

Sheet Read Me
A1: NAPOR: Risk Assessment - Iran-US War
A2: NAPOR is the underlying engine (event log, credibility, chains, phases, forecasts). NAPOR: Risk Assessment applies it to lay out the options and the risks and pros of each one. It does not pick an option. Built by Sidd.
A4: What this is
A5: A structured, dated log of US/Israel-Iran war events from Feb 28, 2026 to Oct 26, 2026, built for computing base rates (how often does X follow Y, and how fast) rather than for narrative reading.
A7: Sheets
A8: Event Log - every event, one row each, with a Trigger ID column pointing to the row that caused it, where reporting says so. Columns N-O count the reports behind each event and how many different independent or official outlets they come from.
A9: Credibility (0-1) - every report gets a weight = source score x fit score. Source score: credible outlet or official statement 0.80, other outlet 0.60, Iranian state media 0.30 (it can only show what Iran claims). Fit score (how sure we are the story is about this event): read in full 1.00, headline only 0.80, outlet named but story not saved 0.65. Reports under 0.30 do not count. An event combines its reports, each outlet counted once, as 1 - (1-w1)(1-w2)..., the chance that not every outlet got it wrong: one full-text credible story = 0.80, two different outlets = 0.96. Partly verified rows are multiplied by 0.8; Not supported rows are capped at 0.20. RULE: only events at 0.50 or above are used in the statistics; 0.50-0.65 is used but flagged 'use with caution'. The Confidence column (High 0.80+, Medium 0.50-0.80, Low under 0.50) now comes from this score. This is a scoring rule, not a statistical confidence interval.
A10: Chains & Phases - every event is tagged with the war phase it happened in (open war, fragile ceasefire, low-intensity war, holding pattern) and, if it is part of a back-and-forth, a chain ID (T01...). The sheet shows reply rates by phase and how long back-and-forths usually last.
A11: War intensity - a 0-and-up points gauge of how hot the war was in the 14 days before any date (2 per direct strike, 1 per shipping/blockade act, +2 if deadly), banded Quiet/Low/Medium/High. Shown in the Event Log and on Chains & Phases. It did not improve the backtest, so it is a gauge, not an input to the numbers.
A12: Forecast Log - the report card. Predictions are written down before the outcome is known, then resolved and scored (Brier score).
A13: Reports - the ID system. Every news story or official statement gets its own report ID (R0001...) and points to exactly one event ID. Three outlets covering one attack = three reports, one event. Merged duplicates: #76 into #75, #49 into #50, #29 into #28; their reports now point to the surviving event.
A14: Review Queue - pairs of events that might be the same event logged twice, plus new stories waiting for a human to confirm which event they belong to. The matcher is right only about half the time on headlines, so a person makes the call.
... A38: Compiled: 2026-10-28. Sources are cited per row; see Event Log column J. Rows 83-86 were added by a live scanner test (Sept 27-29). Rows 90-105 were added on Oct 11 from credible-outlet research covering Oct 2-11 (no US/Israeli strike on Iran and no Iranian strike on a US base was found in that window; the two Houthi rows are context from the separate Saudi-Houthi front). Rows 106-115 were added by the weekly agent on Oct 19 (Oct 12-18 news, plus catch-up rows for Oct 6 and Oct 8); again no US strike on Iranian territory and no Iranian strike on US forces was found, while attacks on shipping hit a record. Rows 87-89 were added by a live matcher test on genuinely new Oct 1 news - the matcher correctly classified the sanctions and diplomatic-statement rows; it fell back to a generic 'Military/Property' guess on the naval force-posture row since that's a troop deployment, not a strike, and the keyword rules don't have a dedicated bucket for that yet. Source audit: 2 events are still Pending credible sourcing and 4 are Not supported as logged (including #76, a confirmed duplicate of #75); treat those rows, and the Partly verified rows that rest on one side's claims, as leads, not findings.

Sheet Event Log
A1: ID | B1: Date | C1: Actor | D1: Action Type | E1: Target | F1: Detail | G1: Trigger ID | H1: Severity / Casualties | I1: Confidence | J1: Source (credible outlets only) | K1: Source Check | L1: Audit note | M1: Kind of act | N1: Reports | O1: Different outlets (independent + official) | P1: Credibility (0-1) | Q1: Used in stats? | R1: War phase | S1: Chain (thread ID) | T1: War intensity (14 days before)
A2: 1 | B2: 46080 | C2: US | D2: Authorization | E2: Iran | F2: Trump authorizes Operation Epic Fury aboard Air Force One | H2: n/a | I2: High | J2: AP 2026-03-02 | K2: Verified | M2: Diplomatic | N2: 2 | O2: 1 | P2: 0.8 | Q2: Yes | R2: Pre-war standoff | T2: Quiet (0 pts)
A3: 2 | B3: 46081 | C3: US/Israel | D3: Strike (war start) | E3: Iran | F3: Operation Epic Fury opens: Pentagon says 1,000+ targets hit in the first 24 hours; Khamenei and ~40 senior officials killed; a strike near Minab hits a girls' school | H3: Khamenei + ~40 senior officials killed (AP). Minab school: Iranian authorities say at least 175 killed (AP); Minab mayor says 168 (NBC) - Iranian figures; no nation has claimed the strike (AP) | I3: High | J3: AP 2026-03-02; AP 2026-03-04; NBC News 2026-03-03 | K3: Corrected | L3: School toll is 168-175 (Iranian figures), not 148-168. '~900 strikes in 12 hrs' was a US-only figure from an unnamed official (via Fox), so it was dropped for the Pentagon's 1,000+ in 24 hrs. | M3: Kinetic | N3: 3 | O3: 2 | P3: 0.96 | Q3: Yes | R3: Open war | S3: T01 | T3: Quiet (0 pts)
A4: 3 | B4: 46081 | C4: US | D4: Strike | E4: Iran | F4: US strikes hit Iran's navy from the first hours: drone carrier Shahid Bagheri attacked (CENTCOM); Bayandor and Naghdi reported sunk at Konarak (The War Zone) | G4: 2 | H4: Only Shahid Bagheri confirmed hit by CENTCOM; Bayandor/Naghdi sinking per The War Zone, undated; Trump and CENTCOM claimed larger totals | I4: High | J4: USNI News 2026-03-02; The War Zone 2026-03-02; Defense News 2026-03-01 | K4: Corrected | L4: First draft said three ships sunk Feb 28. Credible outlets support 'struck', with only some sinkings reported. | M4: Kinetic | N4: 3 | O4: 3 | P4: 0.99 | Q4: Yes | R4: Open war | S4: T01 | T4: Quiet (0 pts)
A5: 4 | B5: 46081 | C5: Iran | D5: Blockade (de facto) | E5: Strait of Hormuz | F5: IRGC radios ships on VHF that 'no ship is allowed to pass'; Iran does not formally confirm a closure order (Reuters, citing UKMTO and EU Aspides); IRGC-linked Tasnim says the Strait is shut | G5: 2 | H5: Reuters/Kpler: only 105 crossings Mar 1-18 vs ~120/day normal (>95% drop) | I5: High | J5: Reuters 2026-02-28; Reuters 2026-03-19 | K5: Corrected | L5: No formal IRGC declaration found; the '~70% drop' figure was not found and was replaced with Reuters/Kpler data. | M5: Maritime | N5: 2 | O5: 1 | P5: 0.8 | Q5: Yes | R5: Open war | S5: T01 | T5: Quiet (0 pts)
A6: 5 | B6: 46081 | C6: Iran | D6: Retaliation strike | E6: Israel/Gulf | F6: Iran fires missiles at Israel, Kuwait and other Gulf targets; a missile hits a residential block in Tel Aviv; Kuwait International Airport is hit by a drone | G6: 2 | H6: Tel Aviv: 1 killed, 27 injured (Times of Israel); Kuwait airport: minor injuries to staff | I6: Medium | J6: Times of Israel 2026-03-01; Al Jazeera 2026-02-28 | K6: Partly verified | L6: Tel Aviv casualty figures confirmed by Times of Israel (an Israeli outlet; its own pieces vary between 20 and 27 injured). The operation name 'True Promise IV' and the '49 intercepted over Jordan' detail were not found in any allowed outlet and were dropped from the wording. | M6: Kinetic | N6: 3 | O6: 2 | P6: 0.77 | Q6: Yes | R6: Open war | S6: T01 | T6: Quiet (0 pts)
A7: 6 | B7: 46082 | C7: Iran | D7: Retaliation strike | E7: Jordan/Gulf | F7: Iranian strikes on US/allied radar and base sites across the Gulf and Jordan; one THAAD AN/TPY-2 radar in Jordan 'apparently destroyed'; strikes on Manama, Kuwait airport, Abu Dhabi airport and Erbil reported the same day | G7: 2 | H7: One radar (Jordan) apparently destroyed per CNN satellite-image analysis; The War Zone says it 'appears' destroyed; no US confirmation. UAE and Saudi radar damage unclear | I7: Medium | J7: CNN n.d.; The War Zone 2026-03-07; Al Jazeera 2026-03-01 | K7: Partly verified | L7: 'Destroyed' applies to one radar only and rests on imagery analysis, not a US statement. Manama, Kuwait airport, Abu Dhabi airport and Erbil are confirmed by Al Jazeera; Riyadh was not found in the sources read. | M7: Kinetic | N7: 3 | O7: 3 | P7: 0.79 | Q7: Yes | R7: Open war | S7: T01 | T7: High (13 pts)
A8: 7 | B8: 46082 | C8: Iran | D8: Retaliation strike | E8: Kuwait | F8: Strike on a makeshift operations center at the port of Shuaiba, Kuwait | H8: 6 US killed - the first US combat deaths of the war (CENTCOM, AP, CNN) | I8: High | J8: CNN 2026-03-02; AP 2026-03-02 | K8: Corrected | L8: 'Camp Arifjan' is not supported by the retrieved reporting and was dropped. | M8: Kinetic | N8: 2 | O8: 2 | P8: 0.96 | Q8: Yes | R8: Open war | T8: High (13 pts)
A9: 8 | B9: 46081 | C9: US | D9: Strike | E9: Iran | F9: CENTCOM says the Iranian frigate Jamaran was struck at Chabahar at the start of Epic Fury and is 'sinking'; Makran struck at Bandar Abbas (USNI imagery), sinking not confirmed | H9: 1 frigate sinking per CENTCOM; 1 damaged | I9: High | J9: AFP 2026-03-01; USNI News 2026-03-02; The War Zone 2026-03-02 | K9: Corrected | L9: Mar 1 was the CENTCOM report date; the Jamaran strike was Feb 28. Makran sinking is unconfirmed. | M9: Kinetic | N9: 3 | O9: 3 | P9: 0.99 | Q9: Yes | R9: Open war | T9: Quiet (0 pts)
A10: 9 | B10: 46083 | C10: Iran | D10: Retaliation strike | E10: Bahrain/Kuwait | F10: Tanker Stena Imperative hit by suspected Iranian projectiles at a Bahrain port; smoke near the US embassy in Kuwait reported by a witness | H10: USNI: 1 shipyard worker killed and 2 injured ashore at the Bahrain port; crew unhurt. A strike on the Kuwait embassy itself is not confirmed | I10: Medium | J10: USNI News 2026-03-02; Al Jazeera 2026-03-02 | K10: Partly verified | L10: The '1 killed, 2 injured' figure belongs to the Bahrain port incident only. Attribution is 'suspected' Iranian (USNI). 'US embassy Kuwait struck' rested on a witness seeing smoke. | M10: Kinetic | N10: 2 | O10: 2 | P10: 0.77 | Q10: Yes | R10: Open war | T10: High (19 pts)
A11: 10 | B11: 46084 | C11: Israel (IDF) | D11: Strike | E11: Iran | F11: IDF says it struck Iran's Supreme National Security Council complex in Tehran (Mar 2-3) and destroyed a secret underground site on Tehran's outskirts where Iran moved its nuclear work (IDF claim) | H11: n/a - all details are IDF claims; site name spelled 'Minzadehei' by Times of Israel | I11: Medium | J11: Times of Israel 2026-03-04 | K11: Partly verified | L11: Attributed to Israel, not the US. The IDF claims come via Times of Israel. The Expediency Council building appears only in Iran International (not an allowed outlet), so it is not claimed here. | M11: Kinetic | N11: 1 | O11: 1 | P11: 0.64 | Q11: Yes - use with caution | R11: Open war | S11: T02 | T11: High (23 pts)
A12: 11 | B12: 46084 | C12: Iran | D12: Retaliation strike | E12: Saudi Arabia | F12: Two Iranian drones hit the US embassy in Riyadh; limited fire and minor damage per Saudi Defense Ministry (AP) | G12: 10 | H12: No casualties reported | I12: High | J12: AP 2026-03-03 | K12: Corrected | L12: 'CIA annex' is not in the AP reporting and was dropped. Exact date unconfirmed (AP page dated Mar 2-3). | M12: Kinetic | N12: 1 | O12: 1 | P12: 0.8 | Q12: Yes | R12: Open war | S12: T02 | T12: High (23 pts)
A13: 12 | B13: 46084 | C13: Iran | D13: Retaliation strike | E13: Qatar/Saudi | F13: Iranian missile hits the US base at Al Udeid, Qatar (Mar 3); separately a drone attack on Saudi Aramco's Ras Tanura refinery causes a precautionary shutdown (Mar 2, Iran-attributed) | H13: Al Udeid: 2 missiles launched, 1 intercepted, 1 struck the base, no casualties (Qatar Defense Ministry). Ras Tanura: fire from drone-interception debris, some operations halted, no injuries (Saudi energy ministry / SPA) | I13: High | J13: Times of Israel 2026-03-03; AFP 2026-03-02 | K13: Corrected | L13: The first draft lumped two events onto Mar 4. Al Udeid was hit Mar 3; Ras Tanura Mar 2. Iran has denied attacking Aramco, so that attribution rests on Gulf-state sources. | M13: Kinetic | N13: 2 | O13: 2 | P13: 0.93 | Q13: Yes | R13: Open war | T13: High (23 pts)
A14: 13 | B14: 46085 | C14: US | D14: Strike | E14: Iran | F14: A US submarine sinks IRIS Dena ~40nm off Sri Lanka (reported as USS Charlotte by CBS citing unnamed officials; the Pentagon did not name it) | H14: Sri Lankan navy: 87 bodies recovered, 32 rescued (Al Jazeera). Iran's army later claimed 104 killed (Reuters, Mar 8) - a claim | I14: High | J14: Al Jazeera 2026-03-04; Reuters 2026-03-08; Stars and Stripes 2026-07-22 | K14: Corrected | L14: '104 killed, 32 wounded' is an Iranian claim; Sri Lanka reported 87 bodies and 32 rescued. | M14: Kinetic | N14: 3 | O14: 3 | P14: 0.99 | Q14: Yes | R14: Open war | T14: High (29 pts)
A15: 14 | B15: 46091 | C15: Iran | D15: Blockade escalation (mine-laying alleged) | E15: Strait of Hormuz | F15: CENTCOM says US forces destroyed 16 Iranian minelayers near Hormuz on Mar 10; Trump said the US had 'no reports' of mines being laid. Pentagon: Iranian ballistic-missile launches down ~90%, drones ~83% | H15: 16 minelayers claimed destroyed by CENTCOM the same day | I15: High | J15: Reuters 2026-03-11; PBS NewsHour 2026-03-10; CBS News 2026-03-23 | K15: Corrected | L15: Minelayers were claimed destroyed the same day, not later. The '~92%' figure looks like Israel's interception rate, not the fall in Iranian launches. | M15: Maritime | N15: 3 | O15: 3 | P15: 0.99 | Q15: Yes | R15: Open war | T15: High (33 pts)
A16: 15 | B16: 46102 | C16: US | D16: Strike | E16: Strait of Hormuz | F16: CENTCOM (Adm. Cooper, Mar 21) says the US has struck 8,000+ targets, including 130 Iranian vessels, since Feb 28. Iran's Tasnim says at least 16 cargo vessels burned at Bandar Lengeh/Kong after a US-Israeli attack (Mar 20) | H16: 8,000 targets / 130 vessels are CENTCOM claims for the whole war to date; the 16 burned boats are an Iranian claim and Iran calls them civilian cargo boats | I16: High | J16: Stars and Stripes 2026-03-21; AFP 2026-03-20 | K16: Corrected | L16: This was not a campaign that 'began Mar 19': the figures cover the war so far. Re-dated to the Mar 21 CENTCOM briefing. | M16: Kinetic | N16: 2 | O16: 2 | P16: 0.96 | Q16: Yes | R16: Open war | T16: Low (1 pts)
A17: 16 | B17: 46102 | C17: US/Israel (alleged) | D17: Strike (alleged) | E17: Iran | F17: Iran reports an attack on Natanz and blames the US and Israel; the Israeli military denied involvement and the IAEA saw no rise in off-site radiation | H17: n/a - no casualty or damage figures from credible outlets | I17: High | J17: AFP 2026-03-21; AP 2026-03-21; Al Arabiya 2026-03-21 | K17: Corrected | L17: No allowed outlet says this was a US bunker-buster strike; it is confirmed only as Iran's report. Pair 3 rests on Iran treating it as the trigger. | M17: Kinetic | N17: 3 | O17: 3 | P17: 0.98 | Q17: Yes | R17: Open war | S17: T03 | T17: Low (1 pts)
A18: 17 | B18: 46102 | C18: Iran | D18: Retaliation strike | E18: Israel | F18: Iran strikes toward Dimona and Arad and calls it a 'response' to Natanz; Iran did not claim to target the Negev research center | G18: 16 | H18: No deaths; at least 180 wounded (Israel's Health Ministry, via Al Jazeera) | I18: High | J18: AFP 2026-03-21; Al Jazeera 2026-03-21; Euronews 2026-03-22 | K18: Corrected | L18: Wounded count is at least 180, not 175; Iran framed it as a response to Natanz, not as an attack on the research center. | M18: Kinetic | N18: 3 | O18: 3 | P18: 0.98 | Q18: Yes | R18: Open war | S18: T03 | T18: Low (1 pts)
A19: 18 | B19: 46102 | C19: US | D19: Ultimatum | E19: Iran | F19: Trump: 48-hour ultimatum to reopen Strait or face power-plant strikes | H19: n/a | I19: High | J19: Al Jazeera 2026-03-22; Axios 2026-03-22 | K19: Verified | M19: Diplomatic | N19: 2 | O19: 2 | P19: 0.96 | Q19: Yes | R19: Open war | T19: Low (1 pts)
A20: 19 | B20: 46105 | C20: US | D20: Diplomatic proposal | E20: Iran | F20: US 15-point ceasefire plan is passed to Iran through Pakistani intermediaries (AP) | H20: Iran rejected it and offered a counter-plan (AP) | I20: High | J20: AP 2026-03-25; Al Jazeera 2026-04-06 | K20: Corrected | L20: Delivered via Pakistan on or before Mar 24; Mar 25 was the AP publication date. | M20: Diplomatic | N20: 2 | O20: 2 | P20: 0.96 | Q20: Yes | R20: Open war | T20: Medium (7 pts)
A21: 20 | B21: 46107 | C21: Israel | D21: Assassination strike | E21: Iran | F21: Israel says it killed IRGC Navy commander Tangsiri and the IRGC Navy's intelligence chief Rezaei in Bandar Abbas (Israeli claim, Mar 26); Iran confirmed Tangsiri's death on Mar 30 | H21: Tangsiri's death confirmed by the IRGC Mar 30; no Iranian confirmation of Rezaei found (Al Jazeera, AFP, AP) | I21: High | J21: Al Jazeera 2026-03-26; AFP 2026-03-26; AP 2026-03-30 | K21: Corrected | L21: Rezaei is the IRGC Navy's intelligence chief, not Iran's national intelligence chief. 'Blockade architect' label dropped as unverified. | M21: Kinetic | N21: 3 | O21: 3 | P21: 0.99 | Q21: Yes | R21: Open war | S21: T04 | T21: Medium (6 pts)
A22: 21 | B22: 46108 | C22: Iran | D22: Retaliation strike | E22: Saudi Arabia | F22: Strikes Prince Sultan Air Base | G22: 20 | H22: At least 15 US troops wounded, 5 seriously (AP, NPR, Al Jazeera); multiple KC-135 tankers damaged; E-3 AWACS damaged per unnamed sources (WSJ via Al Jazeera) | I22: High | J22: AP 2026-03-27; NPR 2026-03-28; Al Jazeera 2026-03-29 | K22: Corrected | L22: Credible outlets say at least 15 wounded; '29' looks like a cumulative count. | M22: Kinetic | N22: 3 | O22: 3 | P22: 0.99 | Q22: Yes | R22: Open war | S22: T04 | T22: Medium (8 pts)
A23: 22 | B23: 46108 | C23: Iran | D23: Blockade escalation | E23: Strait of Hormuz | F23: IRGC statement bans shipping to/from ports of countries aligned with the US/Israel (reported via Iranian state media; not confirmed by an allowed outlet). Al Jazeera says the Strait was already declared closed on Mar 2 | H23: The '20,000 mariners / 2,000 ships' figure is an IMO number from Mar 25, before this date | I23: Low | J23: Al Jazeera 2026-03-16 | K23: Not supported | L23: Not a new 'total closure': Al Jazeera (Mar 16) says the Strait was declared closed Mar 2. The Mar 27 statement is sourced only to Iranian state media via non-allowed outlets. | M23: Maritime | N23: 1 | O23: 1 | P23: 0.2 | Q23: No - credibility below 0.50 | R23: Open war | T23: Medium (8 pts)
A24: 23 | B24: 46112 | C24: US | D24: Strike | E24: Iran | F24: Joint Chiefs Chairman Caine announces the first overland B-52 missions (NYT, Mar 31); strikes on an Isfahan ammunition depot reported separately by the WSJ (not read directly) | H24: n/a | I24: High | J24: The New York Times 2026-03-31 | K24: Corrected | L24: Mar 31 is the announcement date. No outlet read ties the B-52s to Isfahan or says when the flights began. | M24: Kinetic | N24: 1 | O24: 1 | P24: 0.8 | Q24: Yes | R24: Open war | T24: Medium (10 pts)
A25: 24 | B25: 46112 | C25: Pakistan/China | D25: Diplomatic proposal | E25: Iran/US | F25: China-Pakistan '5-point initiative' ceasefire proposal | H25: n/a | I25: High | J25: Axios 2026-03-31 | K25: Verified | M25: Diplomatic | N25: 1 | O25: 1 | P25: 0.8 | Q25: Yes | R25: Open war | T25: Medium (10 pts)
A26: 25 | B26: 46114 | C26: US | D26: Strike | E26: Iran | F26: Destroys B1 bridge (Tehran-Karaj) during a family holiday gathering below | H26: 8 killed, 95 wounded per Iran's Alborz deputy governor (AFP; not independently verified); Iranian state TV first reported 2 (Al Jazeera headline: 2 killed) | I26: High | J26: The War Zone 2026-04-02; AFP 2026-04-03; Al Jazeera 2026-04-06 | K26: Verified | L26: Casualty figures are Iranian claims and vary by outlet. | M26: Kinetic | N26: 3 | O26: 3 | P26: 0.99 | Q26: Yes | R26: Open war | T26: High (12 pts)
A27: 26 | B27: 46115 | C27: Iran | D27: Air defense | E27: US | F27: Iran shoots down a US F-15E over Iran (ABC); an A-10 is hit separately and crashes in an allied country, its pilot rescued | H27: F-15E: one crew member rescued, the other's status unknown when ABC reported on Apr 4; two rescue helicopters hit but landed safely | I27: High | J27: ABC News 2026-04-04 | K27: Corrected | L27: 'Both crews rescued' is not confirmed by an allowed outlet; the A-10 did not go down over Iran. | M27: Kinetic | N27: 1 | O27: 1 | P27: 0.8 | Q27: Yes | R27: Open war | T27: High (16 pts)
A28: 27 | B28: 46118 | C28: Pakistan | D28: Diplomatic proposal | E28: Iran/US | F28: Pakistan-mediated 45-day ceasefire framework; Iran says it will not reopen the Strait for a temporary ceasefire and sends a 10-point response (Al Jazeera, Reuters) | H28: Iran did not accept; counter-proposal sent | I28: High | J28: Al Jazeera 2026-04-06; Reuters 2026-04-06 | K28: Corrected | L28: Date is Apr 6, not Apr 5. Iran did not flatly reject talks. | M28: Diplomatic | N28: 3 | O28: 2 | P28: 0.96 | Q28: Yes | R28: Open war | T28: High (12 pts)
A29: 28 | B29: 46119 | C29: US/Iran | D29: Ceasefire announcement | E29: - | F29: Trump announces a two-week ceasefire on Truth Social after Pakistan's PM Sharif asks him to extend his deadline; Iran's Supreme National Security Council accepts (Reuters, AP). Apr 7 US time / Apr 8 Gulf time | H29: n/a | I29: High | J29: Reuters 2026-04-07; AP 2026-04-07; AP 2026-04-08 | K29: Corrected | L29: No credible outlet names VP Vance as the channel; Pakistan's leaders are named. | M29: Diplomatic | N29: 6 | O29: 2 | P29: 0.96 | Q29: Yes | R29: Open war | S29: T05 | T29: High (12 pts)
A30: 29 | B30: 46120 | C30: US/Iran/Pakistan | D30: Ceasefire signed | E30: - | F30: UNSUPPORTED AS LOGGED: no credible outlet reports a formally signed ceasefire with these terms. AP describes the Apr 7-8 ceasefire as built on a disputed 10-point Iranian plan with differing Farsi and English versions. Likely a duplicate of #28 | H30: n/a | I30: Merged | J30: AP 2026-04-07; AP 2026-04-08; Reuters 2026-04-07 | K30: Not supported | L30: Searched; AP and Reuters report no signed document and none of the listed terms (sanctions relief, frozen-asset release). Row kept only because other rows point to it. Merged into #28 (same Apr 7-8 ceasefire; no signed document or listed terms were ever reported). | M30: Diplomatic | N30: 0 | O30: 0 | Q30: No - merged duplicate | R30: Fragile ceasefire | T30: High (12 pts)
A31: 30 | B31: 46120 | C31: Israel | D31: Ceasefire violation | E31: Lebanon | F31: Israel strikes 100+ targets across Beirut, southern Lebanon and the Bekaa in about 10 minutes, within hours of the ceasefire (AP) | G31: 28 | H31: Lebanon's health ministry: at least 112 killed in the first count, later 182 (AP) | I31: High | J31: AP 2026-04-08; Reuters 2026-04-09; Al Jazeera 2026-04-08 | K31: Verified | L31: 'Operation Eternal Darkness' name appears only in Israeli outlets (ynet, i24), not in allowed ones, so it was dropped. | M31: Kinetic | N31: 3 | O31: 3 | P31: 0.99 | Q31: Yes | R31: Fragile ceasefire | S31: T05 | T31: High (12 pts)
A32: 31 | B32: 46120 | C32: Iran | D32: Blockade re-escalation | E32: Strait of Hormuz | F32: Iran restricts/resumes blockade, citing the Lebanon strikes as a ceasefire violation | G32: 30 | H32: n/a | I32: High | J32: AP 2026-04-08; The War Zone 2026-04-09; Reuters 2026-04-09 | K32: Verified | M32: Maritime | N32: 3 | O32: 3 | P32: 0.99 | Q32: Yes | R32: Fragile ceasefire | S32: T05 | T32: High (12 pts)
A33: 32 | B33: 46120 | C33: UAE | D33: Strike (covert) | E33: Iran | F33: UAE strikes Lavan Island oil refinery (only revealed later via WSJ/Bloomberg, May 11) | H33: Major fire at the refinery; WSJ reportedly said a significant part of capacity was knocked out for several months (seen via a secondary summary only) | I33: Medium | J33: Times of Israel 2026-04-08; Times of Israel 2026-05-12; Times of Israel 2026-05-30 | K33: Partly verified | L33: Event confirmed; details revealed May 11-12 (WSJ/Bloomberg). 'Crippled for months' is stronger than what could be read. | M33: Kinetic | N33: 4 | O33: 1 | P33: 0.64 | Q33: Yes - use with caution | R33: Fragile ceasefire | T33: High (12 pts)
A34: 33 | B34: 46123 | C34: US | D34: Blockade-adjacent action | E34: Strait of Hormuz | F34: US Navy destroyers transit the Strait for the first time since the war began (mine-clearance framing) | H34: Iran calls it a ceasefire violation | I34: High | J34: USNI News 2026-04-11; Axios 2026-04-11 | K34: Verified | M34: Maritime | N34: 2 | O34: 2 | P34: 0.96 | Q34: Yes | R34: Fragile ceasefire | T34: High (15 pts)
A35: 34 | B35: 46123 | C35: US/Iran/Pakistan | D35: Diplomatic talks | E35: - | F35: Islamabad Talks: 21 hours of negotiation, collapse without agreement | H35: Failed - Araghchi: 'inches away' but accused US of moving goalposts | I35: High | J35: AP 2026-04-11; Axios 2026-04-12; Times of Israel 2026-04-12 | K35: Verified | M35: Diplomatic | N35: 3 | O35: 3 | P35: 0.99 | Q35: Yes | R35: Fragile ceasefire | S35: T06 | T35: High (15 pts)
A36: 35 | B36: 46125 | C36: US | D36: Blockade start | E36: Iran | F36: US naval blockade of Iran begins | G36: 34 | H36: n/a | I36: High | J36: USNI News 2026-04-11; Axios 2026-04-12; Al Jazeera 2026-04-13 | K36: Verified | M36: Maritime | N36: 3 | O36: 3 | P36: 0.99 | Q36: Yes | R36: Fragile ceasefire | S36: T06 | T36: High (16 pts)
A37: 36 | B37: 46130 | C37: Iran | D37: Blockade re-escalation | E37: Strait of Hormuz | F37: Iran announces the Strait closed again, citing continuation of the US blockade | G37: 35 | H37: n/a | I37: High | J37: AP 2026-04-18 | K37: Verified | M37: Maritime | N37: 1 | O37: 1 | P37: 0.8 | Q37: Yes | R37: Fragile ceasefire | S37: T06 | T37: Medium (9 pts)
A38: 37 | B38: 46131 | C38: US | D38: Seizure | E38: Iranian shipping | F38: US disables the Iranian container ship Touska with gunfire from USS Spruance (Apr 19, USNI); tankers Tifani and Majestic X interdicted in the Indian Ocean around Apr 22-24 (dates not confirmed by an allowed outlet) | H38: 3 vessels | I38: High | J38: USNI News 2026-04-19 | K38: Corrected | L38: Touska is a container ship, not a tanker. Tifani/Majestic X dates conflict across outlets (Apr 22-24). | M38: Maritime | N38: 1 | O38: 1 | P38: 0.8 | Q38: Yes | R38: Fragile ceasefire | S38: T07 | T38: Medium (10 pts)
A39: 38 | B39: 46134 | C39: Iran | D39: Seizure (retaliation) | E39: Shipping | F39: IRGC seizes container ships MSC Epaminondas and MSC Francesca | G39: 37 | H39: No casualties (AFP, Reuters) | I39: High | J39: AFP 2026-04-22; Reuters 2026-04-23 | K39: Verified | L39: Reuters ties it to the US seizure of the Touska; the IRGC's own stated reasons were blockade and permit violations. | M39: Maritime | N39: 2 | O39: 2 | P39: 0.96 | Q39: Yes | R39: Fragile ceasefire | S39: T07 | T39: Medium (11 pts)
A40: 39 | B40: 46143 | C40: Iran | D40: Incursion | E40: Kuwait | F40: Bubiyan Island raid attempt: 6 IRGC troops by fishing boat, 4 detained, 2 escape; Kuwait announced it on May 12 | H40: 1 injured: a 'security official' (AP) or 'service member' (Al Jazeera); Iran says it was a navigation error | I40: High | J40: Al Jazeera 2026-05-12; AP 2026-05-12 | K40: Verified | L40: Incident May 1, announced May 12. Injured person is described differently by AP and Al Jazeera. | M40: Kinetic | N40: 2 | O40: 2 | P40: 0.96 | Q40: Yes | R40: Fragile ceasefire | T40: Low (3 pts)
...

Sheet Action-Reaction Pairs
A1: Pair ID | B1: Trigger ID | C1: Trigger Date | D1: Trigger Actor | E1: Trigger Action | F1: Response ID | G1: Response Date | H1: Response Actor | I1: Response Action | J1: Response Time (days) | K1: Trigger Category | L1: Response Caused Casualties | M1: Notes
A2: 1 | B2: 2 | C2: =INDEX('Event Log'!$B$2:$B$194,MATCH(B2,'Event Log'!$A$2:$A$194,0)) -> 46081 | D2: =INDEX('Event Log'!$C$2:$C$194,MATCH(B2,'Event Log'!$A$2:$A$194,0)) -> US/Israel | E2: =INDEX('Event Log'!$F$2:$F$194,MATCH(B2,'Event Log'!$A$2:$A$194,0)) -> Operation Epic Fury opens: Pentagon says 1,000+ targets hit in the first 24 hours; Khamenei and ~40 senior officials killed; a strike near Minab hits a girls' school | F2: 5 | G2: =INDEX('Event Log'!$B$2:$B$194,MATCH(F2,'Event Log'!$A$2:$A$194,0)) -> 46081 | H2: =INDEX('Event Log'!$C$2:$C$194,MATCH(F2,'Event Log'!$A$2:$A$194,0)) -> Iran | I2: =INDEX('Event Log'!$F$2:$F$194,MATCH(F2,'Event Log'!$A$2:$A$194,0)) -> Iran fires missiles at Israel, Kuwait and other Gulf targets; a missile hits a residential block in Tel Aviv; Kuwait International Airport is hit by a drone | J2: =G2-C2 -> 0 | K2: Personnel/Casualty | L2: Y | M2: Iran's opening retaliation wave, same day as the initial US/Israeli strikes that killed Khamenei and, per Iranian officials, 168-175 at a school
A3: 2 | B3: 10 | C3: =INDEX('Event Log'!$B$2:$B$194,MATCH(B3,'Event Log'!$A$2:$A$194,0)) -> 46084 | D3: =INDEX('Event Log'!$C$2:$C$194,MATCH(B3,'Event Log'!$A$2:$A$194,0)) -> Israel (IDF) | E3: =INDEX('Event Log'!$F$2:$F$194,MATCH(B3,'Event Log'!$A$2:$A$194,0)) -> IDF says it struck Iran's Supreme National Security Council complex in Tehran (Mar 2-3) and destroyed a secret underground site on Tehran's outskirts where Iran moved its nuclear work (IDF claim) | F3: 11 | G3: =INDEX('Event Log'!$B$2:$B$194,MATCH(F3,'Event Log'!$A$2:$A$194,0)) -> 46084 | H3: =INDEX('Event Log'!$C$2:$C$194,MATCH(F3,'Event Log'!$A$2:$A$194,0)) -> Iran | I3: =INDEX('Event Log'!$F$2:$F$194,MATCH(F3,'Event Log'!$A$2:$A$194,0)) -> Two Iranian drones hit the US embassy in Riyadh; limited fire and minor damage per Saudi Defense Ministry (AP) | J3: =G3-C3 -> 0 | K3: Military/Property | L3: N | M3: Retaliation against a symbolic/soft target (embassy annex) rather than in kind
A4: 3 | B4: 16 | C4: =INDEX('Event Log'!$B$2:$B$194,MATCH(B4,'Event Log'!$A$2:$A$194,0)) -> 46102 | D4: =INDEX('Event Log'!$C$2:$C$194,MATCH(B4,'Event Log'!$A$2:$A$194,0)) -> US/Israel (alleged) | E4: =INDEX('Event Log'!$F$2:$F$194,MATCH(B4,'Event Log'!$A$2:$A$194,0)) -> Iran reports an attack on Natanz and blames the US and Israel; the Israeli military denied involvement and the IAEA saw no rise in off-site radiation | F4: 17 | G4: =INDEX('Event Log'!$B$2:$B$194,MATCH(F4,'Event Log'!$A$2:$A$194,0)) -> 46102 | H4: =INDEX('Event Log'!$C$2:$C$194,MATCH(F4,'Event Log'!$A$2:$A$194,0)) -> Iran | I4: =INDEX('Event Log'!$F$2:$F$194,MATCH(F4,'Event Log'!$A$2:$A$194,0)) -> Iran strikes toward Dimona and Arad and calls it a 'response' to Natanz; Iran did not claim to target the Negev research center | J4: =G4-C4 -> 0 | K4: Military/Property | L4: Y | M4: Iran hits Israeli nuclear-adjacent sites in response to a US strike on Natanz
A5: 4 | B5: 20 | C5: =INDEX('Event Log'!$B$2:$B$194,MATCH(B5,'Event Log'!$A$2:$A$194,0)) -> 46107 | D5: =INDEX('Event Log'!$C$2:$C$194,MATCH(B5,'Event Log'!$A$2:$A$194,0)) -> Israel | E5: =INDEX('Event Log'!$F$2:$F$194,MATCH(B5,'Event Log'!$A$2:$A$194,0)) -> Israel says it killed IRGC Navy commander Tangsiri and the IRGC Navy's intelligence chief Rezaei in Bandar Abbas (Israeli claim, Mar 26); Iran confirmed Tangsiri's death on Mar 30 | F5: 21 | G5: =INDEX('Event Log'!$B$2:$B$194,MATCH(F5,'Event Log'!$A$2:$A$194,0)) -> 46108 | H5: =INDEX('Event Log'!$C$2:$C$194,MATCH(F5,'Event Log'!$A$2:$A$194,0)) -> Iran | I5: =INDEX('Event Log'!$F$2:$F$194,MATCH(F5,'Event Log'!$A$2:$A$194,0)) -> Strikes Prince Sultan Air Base | J5: =G5-C5 -> 1 | K5: Personnel/Casualty | L5: Y | M5: Retaliation for Israel's strike that it says killed the IRGC Navy commander and its intelligence chief (Iran confirmed only the commander, Mar 30)
A6: 5 | B6: 30 | C6: =INDEX('Event Log'!$B$2:$B$194,MATCH(B6,'Event Log'!$A$2:$A$194,0)) -> 46120 | D6: =INDEX('Event Log'!$C$2:$C$194,MATCH(B6,'Event Log'!$A$2:$A$194,0)) -> Israel | E6: =INDEX('Event Log'!$F$2:$F$194,MATCH(B6,'Event Log'!$A$2:$A$194,0)) -> Israel strikes 100+ targets across Beirut, southern Lebanon and the Bekaa in about 10 minutes, within hours of the ceasefire (AP) | F6: 31 | G6: =INDEX('Event Log'!$B$2:$B$194,MATCH(F6,'Event Log'!$A$2:$A$194,0)) -> 46120 | H6: =INDEX('Event Log'!$C$2:$C$194,MATCH(F6,'Event Log'!$A$2:$A$194,0)) -> Iran | I6: =INDEX('Event Log'!$F$2:$F$194,MATCH(F6,'Event Log'!$A$2:$A$194,0)) -> Iran restricts/resumes blockade, citing the Lebanon strikes as a ceasefire violation | J6: =G6-C6 -> 0 | K6: Political/Diplomatic | L6: N | M6: Iran treats an Israeli action as breaking a US-brokered ceasefire
A7: 6 | B7: 34 | C7: =INDEX('Event Log'!$B$2:$B$194,MATCH(B7,'Event Log'!$A$2:$A$194,0)) -> 46123 | D7: =INDEX('Event Log'!$C$2:$C$194,MATCH(B7,'Event Log'!$A$2:$A$194,0)) -> US/Iran/Pakistan | E7: =INDEX('Event Log'!$F$2:$F$194,MATCH(B7,'Event Log'!$A$2:$A$194,0)) -> Islamabad Talks: 21 hours of negotiation, collapse without agreement | F7: 35 | G7: =INDEX('Event Log'!$B$2:$B$194,MATCH(F7,'Event Log'!$A$2:$A$194,0)) -> 46125 | H7: =INDEX('Event Log'!$C$2:$C$194,MATCH(F7,'Event Log'!$A$2:$A$194,0)) -> US | I7: =INDEX('Event Log'!$F$2:$F$194,MATCH(F7,'Event Log'!$A$2:$A$194,0)) -> US naval blockade of Iran begins | J7: =G7-C7 -> 2 | K7: Political/Diplomatic | L7: N | M7: Failed talks preceded the US blockade decision
A8: 7 | B8: 35 | C8: =INDEX('Event Log'!$B$2:$B$194,MATCH(B8,'Event Log'!$A$2:$A$194,0)) -> 46125 | D8: =INDEX('Event Log'!$C$2:$C$194,MATCH(B8,'Event Log'!$A$2:$A$194,0)) -> US | E8: =INDEX('Event Log'!$F$2:$F$194,MATCH(B8,'Event Log'!$A$2:$A$194,0)) -> US naval blockade of Iran begins | F8: 36 | G8: =INDEX('Event Log'!$B$2:$B$194,MATCH(F8,'Event Log'!$A$2:$A$194,0)) -> 46130 | H8: =INDEX('Event Log'!$C$2:$C$194,MATCH(F8,'Event Log'!$A$2:$A$194,0)) -> Iran | I8: =INDEX('Event Log'!$F$2:$F$194,MATCH(F8,'Event Log'!$A$2:$A$194,0)) -> Iran announces the Strait closed again, citing continuation of the US blockade | J8: =G8-C8 -> 5 | K8: Economic/Blockade | L8: N | M8: Iran reopens hostilities citing the new US blockade
A9: 8 | B9: 37 | C9: =INDEX('Event Log'!$B$2:$B$194,MATCH(B9,'Event Log'!$A$2:$A$194,0)) -> 46131 | D9: =INDEX('Event Log'!$C$2:$C$194,MATCH(B9,'Event Log'!$A$2:$A$194,0)) -> US | E9: =INDEX('Event Log'!$F$2:$F$194,MATCH(B9,'Event Log'!$A$2:$A$194,0)) -> US disables the Iranian container ship Touska with gunfire from USS Spruance (Apr 19, USNI); tankers Tifani and Majestic X interdicted in the Indian Ocean around Apr 22-24 (dates not confirmed by an allowed outlet) | F9: 38 | G9: =INDEX('Event Log'!$B$2:$B$194,MATCH(F9,'Event Log'!$A$2:$A$194,0)) -> 46134 | H9: =INDEX('Event Log'!$C$2:$C$194,MATCH(F9,'Event Log'!$A$2:$A$194,0)) -> Iran | I9: =INDEX('Event Log'!$F$2:$F$194,MATCH(F9,'Event Log'!$A$2:$A$194,0)) -> IRGC seizes container ships MSC Epaminondas and MSC Francesca | J9: =G9-C9 -> 3 | K9: Economic/Blockade | L9: N | M9: Direct tit-for-tat ship seizures
A10: 9 | B10: 41 | C10: =INDEX('Event Log'!$B$2:$B$194,MATCH(B10,'Event Log'!$A$2:$A$194,0)) -> 46149 | D10: =INDEX('Event Log'!$C$2:$C$194,MATCH(B10,'Event Log'!$A$2:$A$194,0)) -> Iran | E10: =INDEX('Event Log'!$F$2:$F$194,MATCH(B10,'Event Log'!$A$2:$A$194,0)) -> Missiles, drones and small boats attack 3 US destroyers transiting the Strait | F10: 42 | G10: =INDEX('Event Log'!$B$2:$B$194,MATCH(F10,'Event Log'!$A$2:$A$194,0)) -> 46149 | H10: =INDEX('Event Log'!$C$2:$C$194,MATCH(F10,'Event Log'!$A$2:$A$194,0)) -> US | I10: =INDEX('Event Log'!$F$2:$F$194,MATCH(F10,'Event Log'!$A$2:$A$194,0)) -> US strikes sites near Bandar Abbas and Qeshm Island (CENTCOM did not name the IRGC) | J10: =G10-C10 -> 0 | K10: Military/Property | L10: N | M10: US strikes back same day after its destroyers are attacked (no casualties)
A11: 10 | B11: 44 | C11: =INDEX('Event Log'!$B$2:$B$194,MATCH(B11,'Event Log'!$A$2:$A$194,0)) -> 46181 | D11: =INDEX('Event Log'!$C$2:$C$194,MATCH(B11,'Event Log'!$A$2:$A$194,0)) -> Israel | E11: =INDEX('Event Log'!$F$2:$F$194,MATCH(B11,'Event Log'!$A$2:$A$194,0)) -> Strikes kill members of Iran's air-defense units | F11: 45 | G11: =INDEX('Event Log'!$B$2:$B$194,MATCH(F11,'Event Log'!$A$2:$A$194,0)) -> 46181 | H11: =INDEX('Event Log'!$C$2:$C$194,MATCH(F11,'Event Log'!$A$2:$A$194,0)) -> Iran | I11: =INDEX('Event Log'!$F$2:$F$194,MATCH(F11,'Event Log'!$A$2:$A$194,0)) -> Downs a US Apache helicopter over the Strait (US says a Shahed drone did it) | J11: =G11-C11 -> 0 | K11: Personnel/Casualty | L11: N | M11: Iran/US disagree on mechanism, but timing ties this to the preceding Israeli strike that killed air-defense personnel
A12: 11 | B12: 45 | C12: =INDEX('Event Log'!$B$2:$B$194,MATCH(B12,'Event Log'!$A$2:$A$194,0)) -> 46181 | D12: =INDEX('Event Log'!$C$2:$C$194,MATCH(B12,'Event Log'!$A$2:$A$194,0)) -> Iran | E12: =INDEX('Event Log'!$F$2:$F$194,MATCH(B12,'Event Log'!$A$2:$A$194,0)) -> Downs a US Apache helicopter over the Strait (US says a Shahed drone did it) | F12: 46 | G12: =INDEX('Event Log'!$B$2:$B$194,MATCH(F12,'Event Log'!$A$2:$A$194,0)) -> 46182 | H12: =INDEX('Event Log'!$C$2:$C$194,MATCH(F12,'Event Log'!$A$2:$A$194,0)) -> US | I12: =INDEX('Event Log'!$F$2:$F$194,MATCH(F12,'Event Log'!$A$2:$A$194,0)) -> US strikes Iranian air-defense, ground-control and surveillance radar sites near the Strait after Iran downs a US Apache (CENTCOM: 'proportional response') | J12: =G12-C12 -> 1 | K12: Military/Property | L12: N | M12: US retaliates for the downed Apache within hours (crew survived)
A13: 12 | B13: 46 | C13: =INDEX('Event Log'!$B$2:$B$194,MATCH(B13,'Event Log'!$A$2:$A$194,0)) -> 46182 | D13: =INDEX('Event Log'!$C$2:$C$194,MATCH(B13,'Event Log'!$A$2:$A$194,0)) -> US | E13: =INDEX('Event Log'!$F$2:$F$194,MATCH(B13,'Event Log'!$A$2:$A$194,0)) -> US strikes Iranian air-defense, ground-control and surveillance radar sites near the Strait after Iran downs a US Apache (CENTCOM: 'proportional response') | F13: 47 | G13: =INDEX('Event Log'!$B$2:$B$194,MATCH(F13,'Event Log'!$A$2:$A$194,0)) -> 46183 | H13: =INDEX('Event Log'!$C$2:$C$194,MATCH(F13,'Event Log'!$A$2:$A$194,0)) -> Iran | I13: =INDEX('Event Log'!$F$2:$F$194,MATCH(F13,'Event Log'!$A$2:$A$194,0)) -> Strikes Muwaffaq Salti AB plus bases in Kuwait and Bahrain | J13: =G13-C13 -> 1 | K13: Military/Property | L13: N | M13: Iran retaliates against Jordan for the US's Qeshm/Sirik counterstrikes
... A37: 37 | B37: 255 | C37: =INDEX('Event Log'!$B$2:$B$194,MATCH(B37,'Event Log'!$A$2:$A$194,0)) -> 45830 | D37: =INDEX('Event Log'!$C$2:$C$194,MATCH(B37,'Event Log'!$A$2:$A$194,0)) -> US | E37: =INDEX('Event Log'!$F$2:$F$194,MATCH(B37,'Event Log'!$A$2:$A$194,0)) -> Operation Midnight Hammer: US bombers and missiles strike Iran's Fordow, Natanz and Isfahan nuclear sites | F37: 256 | G37: =INDEX('Event Log'!$B$2:$B$194,MATCH(F37,'Event Log'!$A$2:$A$194,0)) -> 45831 | H37: =INDEX('Event Log'!$C$2:$C$194,MATCH(F37,'Event Log'!$A$2:$A$194,0)) -> Iran | I37: =INDEX('Event Log'!$F$2:$F$194,MATCH(F37,'Event Log'!$A$2:$A$194,0)) -> Iran fires 19 missiles at Al Udeid air base; one hits; Trump thanks Iran for 'early notice' | J37: =G37-C37 -> 1 | K37: Military/Property | L37: N | M37: Iran answers the strikes on its nuclear sites with a telegraphed missile attack on Al Udeid
A39: Average response time (days): | B39: =AVERAGE(J2:J37) -> 1.4166667
A40: Median response time (days): | B40: =MEDIAN(J2:J37) -> 1
A41: Number of pairs (n): | B41: =COUNT(J2:J37) -> 36
A42: Share responded within 1 day: | B42: =COUNTIF(J2:J37,"<=1")/COUNT(J2:J37) -> 0.66666667
A44: Pairs on hold (not counted in any statistic):
A45: Pair 21: trigger #75 -> response #76 (Military/Property). Iran follows up with a larger second wave the next day, after a strike that destroyed aircraft but killed no one Held because: event #76 is likely a duplicate of #75.

Sheet Factor Analysis
A1: Which factor drives a fast, reliable response?
A2: Each action-reaction pair is tagged by what kind of cost the trigger imposed on the side that responded. Grouping by that tag shows which kind of cost provokes the fastest, most reliable comeback - this is the closest thing this dataset has to 'which factor the country weighs most.'
A5: Trigger Category | B5: n (pairs) | C5: Mean response time (days) | D5: Share responded within 1 day | E5: 95% CI low | F5: 95% CI high | G5: Share responded within 2 days | H5: Share of responses that cause casualties
A6: Personnel/Casualty | B6: =COUNTIF('Action-Reaction Pairs'!$K$2:$K$37,A6) -> 11 | C6: =AVERAGEIF('Action-Reaction Pairs'!$K$2:$K$37,A6,'Action-Reaction Pairs'!$J$2:$J$37) -> 1.5454545 | D6: =SUMPRODUCT(('Action-Reaction Pairs'!$K$2:$K$37=A6)*('Action-Reaction Pairs'!$J$2:$J$37<=1))/COUNTIF('Action-Reaction Pairs'!$K$2:$K$37,A6) -> 0.63636364 | E6: =MAX(0,((D6+(1.96^2)/(2*B6)))/(1+(1.96^2)/B6)-(1.96*SQRT((D6*(1-D6)/B6)+((1.96^2)/(4*B6^2))))/(1+(1.96^2)/B6)) -> 0.35379678 | F6: =MIN(1,((D6+(1.96^2)/(2*B6)))/(1+(1.96^2)/B6)+(1.96*SQRT((D6*(1-D6)/B6)+((1.96^2)/(4*B6^2))))/(1+(1.96^2)/B6)) -> 0.84833776 | G6: =SUMPRODUCT(('Action-Reaction Pairs'!$K$2:$K$37=A6)*('Action-Reaction Pairs'!$J$2:$J$37<=2))/COUNTIF('Action-Reaction Pairs'!$K$2:$K$37,A6) -> 0.81818182 | H6: =COUNTIFS('Action-Reaction Pairs'!$K$2:$K$37,A6,'Action-Reaction Pairs'!$L$2:$L$37,"Y")/COUNTIF('Action-Reaction Pairs'!$K$2:$K$37,A6) -> 0.36363636
A7: Military/Property | B7: =COUNTIF('Action-Reaction Pairs'!$K$2:$K$37,A7) -> 15 | C7: =AVERAGEIF('Action-Reaction Pairs'!$K$2:$K$37,A7,'Action-Reaction Pairs'!$J$2:$J$37) -> 1 | D7: =SUMPRODUCT(('Action-Reaction Pairs'!$K$2:$K$37=A7)*('Action-Reaction Pairs'!$J$2:$J$37<=1))/COUNTIF('Action-Reaction Pairs'!$K$2:$K$37,A7) -> 0.8 | E7: =MAX(0,((D7+(1.96^2)/(2*B7)))/(1+(1.96^2)/B7)-(1.96*SQRT((D7*(1-D7)/B7)+((1.96^2)/(4*B7^2))))/(1+(1.96^2)/B7)) -> 0.54814065 | F7: =MIN(1,((D7+(1.96^2)/(2*B7)))/(1+(1.96^2)/B7)+(1.96*SQRT((D7*(1-D7)/B7)+((1.96^2)/(4*B7^2))))/(1+(1.96^2)/B7)) -> 0.92952579 | G7: =SUMPRODUCT(('Action-Reaction Pairs'!$K$2:$K$37=A7)*('Action-Reaction Pairs'!$J$2:$J$37<=2))/COUNTIF('Action-Reaction Pairs'!$K$2:$K$37,A7) -> 0.93333333 | H7: =COUNTIFS('Action-Reaction Pairs'!$K$2:$K$37,A7,'Action-Reaction Pairs'!$L$2:$L$37,"Y")/COUNTIF('Action-Reaction Pairs'!$K$2:$K$37,A7) -> 0.4
A8: Economic/Blockade | B8: =COUNTIF('Action-Reaction Pairs'!$K$2:$K$37,A8) -> 5 | C8: =AVERAGEIF('Action-Reaction Pairs'!$K$2:$K$37,A8,'Action-Reaction Pairs'!$J$2:$J$37) -> 2 | D8: =SUMPRODUCT(('Action-Reaction Pairs'!$K$2:$K$37=A8)*('Action-Reaction Pairs'!$J$2:$J$37<=1))/COUNTIF('Action-Reaction Pairs'!$K$2:$K$37,A8) -> 0.6 | E8: =MAX(0,((D8+(1.96^2)/(2*B8)))/(1+(1.96^2)/B8)-(1.96*SQRT((D8*(1-D8)/B8)+((1.96^2)/(4*B8^2))))/(1+(1.96^2)/B8)) -> 0.23071993 | F8: =MIN(1,((D8+(1.96^2)/(2*B8)))/(1+(1.96^2)/B8)+(1.96*SQRT((D8*(1-D8)/B8)+((1.96^2)/(4*B8^2))))/(1+(1.96^2)/B8)) -> 0.88238177 | G8: =SUMPRODUCT(('Action-Reaction Pairs'!$K$2:$K$37=A8)*('Action-Reaction Pairs'!$J$2:$J$37<=2))/COUNTIF('Action-Reaction Pairs'!$K$2:$K$37,A8) -> 0.6 | H8: =COUNTIFS('Action-Reaction Pairs'!$K$2:$K$37,A8,'Action-Reaction Pairs'!$L$2:$L$37,"Y")/COUNTIF('Action-Reaction Pairs'!$K$2:$K$37,A8) -> 0
A9: Political/Diplomatic | B9: =COUNTIF('Action-Reaction Pairs'!$K$2:$K$37,A9) -> 5 | C9: =AVERAGEIF('Action-Reaction Pairs'!$K$2:$K$37,A9,'Action-Reaction Pairs'!$J$2:$J$37) -> 1.8 | D9: =SUMPRODUCT(('Action-Reaction Pairs'!$K$2:$K$37=A9)*('Action-Reaction Pairs'!$J$2:$J$37<=1))/COUNTIF('Action-Reaction Pairs'!$K$2:$K$37,A9) -> 0.4 | E9: =MAX(0,((D9+(1.96^2)/(2*B9)))/(1+(1.96^2)/B9)-(1.96*SQRT((D9*(1-D9)/B9)+((1.96^2)/(4*B9^2))))/(1+(1.96^2)/B9)) -> 0.11761823 | F9: =MIN(1,((D9+(1.96^2)/(2*B9)))/(1+(1.96^2)/B9)+(1.96*SQRT((D9*(1-D9)/B9)+((1.96^2)/(4*B9^2))))/(1+(1.96^2)/B9)) -> 0.76928007 | G9: =SUMPRODUCT(('Action-Reaction Pairs'!$K$2:$K$37=A9)*('Action-Reaction Pairs'!$J$2:$J$37<=2))/COUNTIF('Action-Reaction Pairs'!$K$2:$K$37,A9) -> 0.6 | H9: =COUNTIFS('Action-Reaction Pairs'!$K$2:$K$37,A9,'Action-Reaction Pairs'!$L$2:$L$37,"Y")/COUNTIF('Action-Reaction Pairs'!$K$2:$K$37,A9) -> 0
A11: Reading this table: 'Personnel/Casualty' pairs are triggers that killed or injured someone (an assassination, a strike that hit a school or a wedding, an attack on air-defense crews). 'Economic/Blockade' pairs are triggers about ships, seizures, sanctions, or oil - no one was hurt.
A13: What it shows, two ways: (1) SPEED/RELIABILITY - triggers that cost human lives get answered faster and more reliably than triggers that only cost money or equipment; economic/blockade moves are the slowest and least certain. (2) COST OF THE COMEBACK - the last column shows how often the response itself produces real casualties, not just a symbolic hit. Personnel/Casualty triggers are answered both fastest AND with the highest chance of a genuinely costly response. Economic/Blockade and Political/Diplomatic triggers have never (in this dataset) drawn a response that killed or injured anyone - the retaliation happens, but it stays contained to property and equipment.
A15: The 95% CI columns are Wilson score intervals on the 'within 1 day' share - the honest range given how few examples each category has. Notice how wide these are (often 30-40 points wide) for the n=4-5 categories - that's the real uncertainty, not a flaw in the formula. Treat the RANKING across categories as solid; treat any single percentage as a rough midpoint of a wide range.
A17: Sample-size warning: each group has 4-10 pairs. This is a real, directionally consistent pattern, not a precise coefficient.
A19: Important limit: every share on this sheet is measured only among pairs where a reply happened. It says how fast and how costly replies are, not whether one comes. For the chance a reply happens at all, see the Trigger Census sheet.

Sheet Trigger Census
A1: How often does a hostile act actually get a reply?
A2: Factor Analysis only sees pairs where a reply happened, so it overstates how reliable replies are. This sheet lists every countable hostile act (strikes, seizures, blockade moves, sanctions) and whether the other side hit back within about 5 days - including the ones where nothing followed. Diplomatic moves are not covered.
A5: Trigger Category | B5: Acts counted | C5: Got a reply | D5: No reply found | E5: Unclear | F5: Unverified (not counted) | G5: P(any reply) LOW | H5: P(any reply) BEST | I5: P(any reply) HIGH | J5: 95% CI low (BEST) | K5: 95% CI high (BEST)
A6: Personnel/Casualty | B6: =C6+D6 -> 7 | C6: =COUNTIFS($F$24:$F$79,A6,$G$24:$G$79,"R-strong")+COUNTIFS($F$24:$F$79,A6,$G$24:$G$79,"R-weak")+COUNTIFS($F$24:$F$79,A6,$G$24:$G$79,"R-proxy") -> 6 | D6: =COUNTIFS($F$24:$F$79,A6,$G$24:$G$79,"N") -> 1 | E6: =COUNTIFS($F$24:$F$79,A6,$G$24:$G$79,"Unclear") -> 0 | F6: =COUNTIFS($F$24:$F$79,A6,$G$24:$G$79,"Unverified") -> 0 | G6: =COUNTIFS($F$24:$F$79,A6,$G$24:$G$79,"R-strong")/(B6+E6) -> 0.71428571 | H6: =C6/B6 -> 0.85714286 | I6: =(C6+E6)/(B6+E6) -> 0.85714286 | J6: =MAX(0,((H6+(1.96^2)/(2*B6)))/(1+(1.96^2)/B6)-(1.96*SQRT((H6*(1-H6)/B6)+((1.96^2)/(4*B6^2))))/(1+(1.96^2)/B6)) -> 0.4868655 | K6: =MIN(1,((H6+(1.96^2)/(2*B6)))/(1+(1.96^2)/B6)+(1.96*SQRT((H6*(1-H6)/B6)+((1.96^2)/(4*B6^2))))/(1+(1.96^2)/B6)) -> 0.97432104
A7: Military/Property | B7: =C7+D7 -> 19 | C7: =COUNTIFS($F$24:$F$79,A7,$G$24:$G$79,"R-strong")+COUNTIFS($F$24:$F$79,A7,$G$24:$G$79,"R-weak")+COUNTIFS($F$24:$F$79,A7,$G$24:$G$79,"R-proxy") -> 17 | D7: =COUNTIFS($F$24:$F$79,A7,$G$24:$G$79,"N") -> 2 | E7: =COUNTIFS($F$24:$F$79,A7,$G$24:$G$79,"Unclear") -> 2 | F7: =COUNTIFS($F$24:$F$79,A7,$G$24:$G$79,"Unverified") -> 1 | G7: =COUNTIFS($F$24:$F$79,A7,$G$24:$G$79,"R-strong")/(B7+E7) -> 0.42857143 | H7: =C7/B7 -> 0.89473684 | I7: =(C7+E7)/(B7+E7) -> 0.9047619 | J7: =MAX(0,((H7+(1.96^2)/(2*B7)))/(1+(1.96^2)/B7)-(1.96*SQRT((H7*(1-H7)/B7)+((1.96^2)/(4*B7^2))))/(1+(1.96^2)/B7)) -> 0.6860545 | K7: =MIN(1,((H7+(1.96^2)/(2*B7)))/(1+(1.96^2)/B7)+(1.96*SQRT((H7*(1-H7)/B7)+((1.96^2)/(4*B7^2))))/(1+(1.96^2)/B7)) -> 0.97064206
A8: Economic/Blockade | B8: =C8+D8 -> 22 | C8: =COUNTIFS($F$24:$F$79,A8,$G$24:$G$79,"R-strong")+COUNTIFS($F$24:$F$79,A8,$G$24:$G$79,"R-weak")+COUNTIFS($F$24:$F$79,A8,$G$24:$G$79,"R-proxy") -> 8 | D8: =COUNTIFS($F$24:$F$79,A8,$G$24:$G$79,"N") -> 14 | E8: =COUNTIFS($F$24:$F$79,A8,$G$24:$G$79,"Unclear") -> 3 | F8: =COUNTIFS($F$24:$F$79,A8,$G$24:$G$79,"Unverified") -> 2 | G8: =COUNTIFS($F$24:$F$79,A8,$G$24:$G$79,"R-strong")/(B8+E8) -> 0.2 | H8: =C8/B8 -> 0.36363636 | I8: =(C8+E8)/(B8+E8) -> 0.44 | J8: =MAX(0,((H8+(1.96^2)/(2*B8)))/(1+(1.96^2)/B8)-(1.96*SQRT((H8*(1-H8)/B8)+((1.96^2)/(4*B8^2))))/(1+(1.96^2)/B8)) -> 0.19732973 | K8: =MIN(1,((H8+(1.96^2)/(2*B8)))/(1+(1.96^2)/B8)+(1.96*SQRT((H8*(1-H8)/B8)+((1.96^2)/(4*B8^2))))/(1+(1.96^2)/B8)) -> 0.57048651
A10: PROVISIONAL. These statuses were first assigned from the Wikipedia-based log and a research pass that used some weak outlets. The log has since been re-sourced to credible outlets (see Event Log column K), which found real errors. Most unclear census rows have now been re-checked (see Evidence quality); a few Unverified rows are still left out of the rates. Many 'reply' calls are R-weak, meaning only timing links the reply to the act. Treat every rate on this sheet as a rough draft. Samples are tiny (about 4-12 acts per category), so the ranges matter more than the point estimates.
A12: Continuous-fighting rule: triggers dated Feb 28-Apr 7 and Jul 7-25 are excluded (except the acts that started those stretches), because while both sides strike each other daily every act is automatically 'answered'. The exclusion list at the bottom names every row moved out.
A14: Status codes: R-strong = reply is in the log with an explicit link. R-weak = a distinct hostile act followed within 5 days but only timing links it. N = checked against outside sources, no reply found (a pause, talks, or rhetoric only). Unclear = sources conflict or are too thin. Unverified = not checked yet, so left out of every rate below.
A16: Three estimates because the coding involves judgment. LOW counts only R-strong as replies and treats R-weak, N and Unclear all as no reply. BEST counts R-strong and R-weak as replies and ignores Unclear. HIGH also counts every Unclear as a reply. If a conclusion only holds under one of the three, it is not solid.
A18: The 95% CI is a Wilson interval around the BEST estimate and shows the sampling uncertainty on top of that judgment range. Samples are small (10-13 acts per category), so treat these as ranges, not points.
A20: Preliminary: the rows marked Unverified (see the Unverified column) have not been checked against outside sources. They are left out of the rates, not assumed to be replies or non-replies.
A23: Trigger ID | B23: Date | C23: Actor | D23: Action Type | E23: What happened | F23: Trigger Category | G23: Status | H23: Evidence / note | I23: Evidence quality
A24: 2 | B24: =INDEX('Event Log'!$B$2:$B$194,MATCH(A24,'Event Log'!$A$2:$A$194,0)) -> 46081 | C24: =INDEX('Event Log'!$C$2:$C$194,MATCH(A24,'Event Log'!$A$2:$A$194,0)) -> US/Israel | D24: =INDEX('Event Log'!$D$2:$D$194,MATCH(A24,'Event Log'!$A$2:$A$194,0)) -> Strike (war start) | E24: =INDEX('Event Log'!$F$2:$F$194,MATCH(A24,'Event Log'!$A$2:$A$194,0)) -> Operation Epic Fury opens: Pentagon says 1,000+ targets hit in the first 24 hours; Khamenei and ~40 senior officials killed; a strike near Minab hits a girls' school | F24: Personnel/Casualty | G24: R-strong | H24: Opening wave; Iran's big retaliation came the same day (pair 1). The act that started the war counts; the rest of Feb 28-Mar 4 is excluded. | I24: Trigger: Corrected. Reply #5: Partly verified
A25: 31 | B25: =INDEX('Event Log'!$B$2:$B$194,MATCH(A25,'Event Log'!$A$2:$A$194,0)) -> 46120 | C25: =INDEX('Event Log'!$C$2:$C$194,MATCH(A25,'Event Log'!$A$2:$A$194,0)) -> Iran | D25: =INDEX('Event Log'!$D$2:$D$194,MATCH(A25,'Event Log'!$A$2:$A$194,0)) -> Blockade re-escalation | E25: =INDEX('Event Log'!$F$2:$F$194,MATCH(A25,'Event Log'!$A$2:$A$194,0)) -> Iran restricts/resumes blockade, citing the Lebanon strikes as a ceasefire violation | F25: Economic/Blockade | G25: R-weak | H25: Iran keeps the Strait mostly shut after the Apr 8 ceasefire, citing Lebanon strikes. The US announced its blockade Apr 12 (in force Apr 13), but outlets tie it to the collapse of the Islamabad talks, not to Iran's restriction. Timing only. | I25: Re-checked (Times of Israel, NPR snippets, Al Jazeera): blockade came Apr 12-13, tied to failed talks. NPR pages were seen only as snippets.
A26: 33 | B26: =INDEX('Event Log'!$B$2:$B$194,MATCH(A26,'Event Log'!$A$2:$A$194,0)) -> 46123 | C26: =INDEX('Event Log'!$C$2:$C$194,MATCH(A26,'Event Log'!$A$2:$A$194,0)) -> US | D26: =INDEX('Event Log'!$D$2:$D$194,MATCH(A26,'Event Log'!$A$2:$A$194,0)) -> Blockade-adjacent action | E26: =INDEX('Event Log'!$F$2:$F$194,MATCH(A26,'Event Log'!$A$2:$A$194,0)) -> US Navy destroyers transit the Strait for the first time since the war began (mine-clearance framing) | F26: Economic/Blockade | G26: N | H26: US destroyers transit the Strait, Apr 11-12. Iran only issued warnings; no kinetic action found Apr 11-16. | I26: Re-checked (Reuters Apr 12, USNI, The War Zone, NPR): only an IRGC warning; no Iranian attacks Apr 11-17.
A27: 35 | B27: =INDEX('Event Log'!$B$2:$B$194,MATCH(A27,'Event Log'!$A$2:$A$194,0)) -> 46125 | C27: =INDEX('Event Log'!$C$2:$C$194,MATCH(A27,'Event Log'!$A$2:$A$194,0)) -> US | D27: =INDEX('Event Log'!$D$2:$D$194,MATCH(A27,'Event Log'!$A$2:$A$194,0)) -> Blockade start | E27: =INDEX('Event Log'!$F$2:$F$194,MATCH(A27,'Event Log'!$A$2:$A$194,0)) -> US naval blockade of Iran begins | F27: Economic/Blockade | G27: R-strong | H27: US blockade begins -> Iran closes the Strait again (pair 7). | I27: Trigger: Verified. Reply #36: Verified
A28: 36 | B28: =INDEX('Event Log'!$B$2:$B$194,MATCH(A28,'Event Log'!$A$2:$A$194,0)) -> 46130 | C28: =INDEX('Event Log'!$C$2:$C$194,MATCH(A28,'Event Log'!$A$2:$A$194,0)) -> Iran | D28: =INDEX('Event Log'!$D$2:$D$194,MATCH(A28,'Event Log'!$A$2:$A$194,0)) -> Blockade re-escalation | E28: =INDEX('Event Log'!$F$2:$F$194,MATCH(A28,'Event Log'!$A$2:$A$194,0)) -> Iran announces the Strait closed again, citing continuation of the US blockade | F28: Economic/Blockade | G28: R-weak | H28: Iran re-closes the Strait Apr 18 over the US blockade. The US seized the container ship Touska about Apr 19 (NPR), but NPR does not say it answers the closure; it is blockade enforcement that was already under way. Timing only. | I28: Re-checked (NPR, Al Jazeera): Touska seized about Apr 19; NPR does not link it to the closure.
A29: 37 | B29: =INDEX('Event Log'!$B$2:$B$194,MATCH(A29,'Event Log'!$A$2:$A$194,0)) -> 46131 | C29: =INDEX('Event Log'!$C$2:$C$194,MATCH(A29,'Event Log'!$A$2:$A$194,0)) -> US | D29: =INDEX('Event Log'!$D$2:$D$194,MATCH(A29,'Event Log'!$A$2:$A$194,0)) -> Seizure | E29: =INDEX('Event Log'!$F$2:$F$194,MATCH(A29,'Event Log'!$A$2:$A$194,0)) -> US disables the Iranian container ship Touska with gunfire from USS Spruance (Apr 19, USNI); tankers Tifani and Majestic X interdicted in the Indian Ocean around Apr 22-24 (dates not confirmed by an allowed outlet) | F29: Economic/Blockade | G29: R-strong | H29: US tanker seizures -> Iran seizes two container ships (pair 8). | I29: Trigger: Corrected. Reply #38: Verified
A30: 38 | B30: =INDEX('Event Log'!$B$2:$B$194,MATCH(A30,'Event Log'!$A$2:$A$194,0)) -> 46134 | C30: =INDEX('Event Log'!$C$2:$C$194,MATCH(A30,'Event Log'!$A$2:$A$194,0)) -> Iran | D30: =INDEX('Event Log'!$D$2:$D$194,MATCH(A30,'Event Log'!$A$2:$A$194,0)) -> Seizure (retaliation) | E30: =INDEX('Event Log'!$F$2:$F$194,MATCH(A30,'Event Log'!$A$2:$A$194,0)) -> IRGC seizes container ships MSC Epaminondas and MSC Francesca | F30: Economic/Blockade | G30: Unverified | H30: Iran seizes two container ships, Apr 22. US reply not checked yet. | I30: Trigger: Verified. Status itself pending credible re-verification
A31: 40 | B31: =INDEX('Event Log'!$B$2:$B$194,MATCH(A31,'Event Log'!$A$2:$A$194,0)) -> 46146 | C31: =INDEX('Event Log'!$C$2:$C$194,MATCH(A31,'Event Log'!$A$2:$A$194,0)) -> US | D31: =INDEX('Event Log'!$D$2:$D$194,MATCH(A31,'Event Log'!$A$2:$A$194,0)) -> Operation | E31: =INDEX('Event Log'!$F$2:$F$194,MATCH(A31,'Event Log'!$A$2:$A$194,0)) -> Operation Project Freedom: announced May 3, began May 4; Navy escort mission for stranded ships; US says six boats sunk (Trump said seven); pause announced May 5 US time (May 6 Gulf time) | F31: Military/Property | G31: R-weak | H31: Project Freedom began May 4 (paused May 5). Iran hit the UAE, a tanker and a cargo ship May 4 (CBS, Al Jazeera), but Al Jazeera stops short of calling it retaliation. Timing only. | I31: Re-checked (CBS, Al Jazeera): Iran attacked the UAE and ships May 4; no outlet calls it retaliation.
A32: 41 | B32: =INDEX('Event Log'!$B$2:$B$194,MATCH(A32,'Event Log'!$A$2:$A$194,0)) -> 46149 | C32: =INDEX('Event Log'!$C$2:$C$194,MATCH(A32,'Event Log'!$A$2:$A$194,0)) -> Iran | D32: =INDEX('Event Log'!$D$2:$D$194,MATCH(A32,'Event Log'!$A$2:$A$194,0)) -> Strike | E32: =INDEX('Event Log'!$F$2:$F$194,MATCH(A32,'Event Log'!$A$2:$A$194,0)) -> Missiles, drones and small boats attack 3 US destroyers transiting the Strait | F32: Military/Property | G32: R-strong | H32: Iran attacks 3 US destroyers -> US strikes back same day (pair 9). | I32: Trigger: Verified. Reply #42: Verified
A33: 42 | B33: =INDEX('Event Log'!$B$2:$B$194,MATCH(A33,'Event Log'!$A$2:$A$194,0)) -> 46149 | C33: =INDEX('Event Log'!$C$2:$C$194,MATCH(A33,'Event Log'!$A$2:$A$194,0)) -> US | D33: =INDEX('Event Log'!$D$2:$D$194,MATCH(A33,'Event Log'!$A$2:$A$194,0)) -> Retaliation strike | E33: =INDEX('Event Log'!$F$2:$F$194,MATCH(A33,'Event Log'!$A$2:$A$194,0)) -> US strikes sites near Bandar Abbas and Qeshm Island (CENTCOM did not name the IRGC) | F33: Military/Property | G33: R-weak | H33: US strikes near Bandar Abbas/Qeshm, May 7. The UAE said it intercepted Iranian missiles and drones May 8 (Reuters), but Iran claimed no reply and CENTCOM disputed Iran's claimed counterattack. Weak call. | I33: Re-checked (Reuters): weak. Reply is the UAE intercepting Iranian missiles May 8, which Iran did not claim.
A34: 44 | B34: =INDEX('Event Log'!$B$2:$B$194,MATCH(A34,'Event Log'!$A$2:$A$194,0)) -> 46181 | C34: =INDEX('Event Log'!$C$2:$C$194,MATCH(A34,'Event Log'!$A$2:$A$194,0)) -> Israel | D34: =INDEX('Event Log'!$D$2:$D$194,MATCH(A34,'Event Log'!$A$2:$A$194,0)) -> Strike (ceasefire violation) | E34: =INDEX('Event Log'!$F$2:$F$194,MATCH(A34,'Event Log'!$A$2:$A$194,0)) -> Strikes kill members of Iran's air-defense units | F34: Personnel/Casualty | G34: R-strong | H34: Israeli strike kills air-defense crews -> Iran downs a US Apache (pair 10). | I34: Trigger: Corrected. Reply #45: Corrected
A35: 45 | B35: =INDEX('Event Log'!$B$2:$B$194,MATCH(A35,'Event Log'!$A$2:$A$194,0)) -> 46181 | C35: =INDEX('Event Log'!$C$2:$C$194,MATCH(A35,'Event Log'!$A$2:$A$194,0)) -> Iran | D35: =INDEX('Event Log'!$D$2:$D$194,MATCH(A35,'Event Log'!$A$2:$A$194,0)) -> Retaliation | E35: =INDEX('Event Log'!$F$2:$F$194,MATCH(A35,'Event Log'!$A$2:$A$194,0)) -> Downs a US Apache helicopter over the Strait (US says a Shahed drone did it) | F35: Military/Property | G35: R-strong | H35: Apache downed -> US self-defense strikes within hours (pair 11). | I35: Trigger: Corrected. Reply #46: Corrected
